15-Nov-23 11:21:28 - ERROR - An error occured in get_response: 
Traceback (most recent call last):
  File "/home/developer/Documents/repository/my-unicorn/cls/decorators.py", line 41, in wrapper
    response = func(*args, **kwargs)
               ^^^^^^^^^^^^^^^^^^^^^
  File "/home/developer/Documents/repository/my-unicorn/cls/AppImageDownloader.py", line 170, in get_response
    raise requests.exceptions.Timeout
requests.exceptions.Timeout
